Workbook

Sheet Sheet2
C1: Q1- which broader category having higher contribution in CPI
C10: Year-month | D10: (All)
A12: for all years | C12: Average of Education | D12: Average of Food and beverages | E12: Average of Household goods and services | F12: Average of Transport and communication | G12: Average of Fuel and light | H12: Average of Recreation and amusement | I12: Average of Personal care and effects | J12: Average of Pan, tobacco and intoxicants | K12: Average of Health | L12: Average of Housing | M12: Average of Miscellaneous | N12: Average of Clothing and footwear
C13: 141.13115 | D13: 142.51003 | E13: 136.68689 | F13: 127.17049 | G13: 136.51003 | H13: 133.8918 | I13: 133.35 | J13: 155.38579 | K13: 138.5168 | L13: 139.256 | M13: 134.23579 | N13: 141.67432
C15: Average of Education | D15: Average of Food and beverages | E15: Average of Household goods and services | F15: Average of Transport and communication | G15: Average of Fuel and light | H15: Average of Recreation and amusement | I15: Average of Personal care and effects | J15: Average of Pan, tobacco and intoxicants | K15: Average of Health | L15: Average of Housing | M15: Average of Miscellaneous | N15: Average of Clothing and footwear
C16: 141.13115 | D16: 142.51003 | E16: 136.68689 | F16: 127.17049 | G16: 136.51003 | H16: 133.8918 | I16: 133.35 | J16: 155.38579 | K16: 138.5168 | L16: 139.256 | M16: 134.23579 | N16: 141.67432
C17: =C16/1660.32*100 -> 8.5002378 | D17: =D16/1660.32*100 -> 8.5832868 | E17: =E16/1660.32*100 -> 8.2325627 | F17: =F16/1660.32*100 -> 7.6593965 | G17: =G16/1660.32*100 -> 8.2219107 | H17: =H16/1660.32*100 -> 8.0642167 | I17: =I16/1660.32*100 -> 8.0315843 | J17: =J16/1660.32*100 -> 9.3587858 | ... N17: =N16/1660.32*100 -> 8.5329525
C18: Average of Education | D18: Average of Food and beverages | E18: Average of Household goods and services | F18: Average of Transport and communication | G18: Average of Fuel and light | H18: Average of Recreation and amusement | I18: Average of Personal care and effects | J18: Average of Pan, tobacco and intoxicants | K18: Average of Health | L18: Average of Housing | M18: Average of Miscellaneous | N18: Average of Clothing and footwear
C19: =C16/1660.32*100 -> 8.5002378 | D19: =D16/1660.32*100 -> 8.5832868 | E19: =E16/1660.32*100 -> 8.2325627 | F19: =F16/1660.32*100 -> 7.6593965 | G19: =G16/1660.32*100 -> 8.2219107 | H19: =H16/1660.32*100 -> 8.0642167 | I19: =I16/1660.32*100 -> 8.0315843 | J19: =J16/1660.32*100 -> 9.3587858 | ... N19: =N16/1660.32*100 -> 8.5329525
A22: for Latest Month may 2023 | C22: Average of Education | D22: Average of Food and beverages | E22: Average of Household goods and services | F22: Average of Transport and communication | G22: Average of Fuel and light | H22: Average of Recreation and amusement | I22: Average of Personal care and effects | J22: Average of Pan, tobacco and intoxicants | K22: Average of Health | L22: Average of Housing | M22: Average of Miscellaneous | N22: Average of Clothing and footwear
C23: 177.4 | D23: 179.66667 | E23: 175.03333 | F23: 164.96667 | G23: 182.9 | H23: 171.4 | I23: 185.23333 | J23: 201.7 | K23: 185.23333 | L23: 163.48333 | M23: 175.6 | N23: 185.43333
C24: =C23/2148.05*100 -> 8.2586532 | D24: =D23/2148.05*100 -> 8.3641753 | E24: =E23/2148.05*100 -> 8.1484757 | F24: =F23/2148.05*100 -> 7.6798336 | G24: =G23/2148.05*100 -> 8.5146994 | H24: =H23/2148.05*100 -> 7.9793301 | I24: =I23/2148.05*100 -> 8.623325 | J24: =J23/2148.05*100 -> 9.3899118 | ... N24: =N23/2148.05*100 -> 8.6326358
C27: As we can see Pan,tabacco and intoxicants category having the higher contribution towards CPI 9.36% in yearly pattern and for latest month may 2023 it is 9.39%
A63: Q2 - Which Year having YOY growth more after 2017 and also reasons
C68: Row Labels | D68: Average of General index
C69: 2013 | D69: 110.01389
C70: 2014 | D70: 117.32778
C71: 2015 | D71: 123.03611
C72: 2016 | D72: 129.1
C73: 2017 | D73: 133.38611
C74: 2018 | D74: 138.66944
C75: 2019 | D75: 144.12727
C76: 2020 | D76: 153.33
C77: 2021 | D77: 161.41667
C78: 2022 | D78: 172.075
C79: 2023 | D79: 177.57333
C80: Grand Total | D80: 139.56448
D83: Years | E83: Y-O-Y Growth | F83: Avg
D84: 2017 | F84: 133.38611
D85: 2018 | E85: =(F85-F84)/F84*100 -> 3.9609321 | F85: 138.66944
D86: 2019 | E86: =(F86-F85)/F85*100 -> 3.935855 | F86: 144.12727
D87: 2020 | E87: =(F87-F86)/F86*100 -> 6.3851394 | F87: 153.33
D88: 2021 | E88: =(F88-F87)/F87*100 -> 5.2740277 | F88: 161.41667
D89: 2022 | E89: =(F89-F88)/F88*100 -> 6.6029943 | F89: 172.075
D90: 2023 | E90: =(F90-F89)/F89*100 -> 3.1953121 | F90: 177.57333
A92: As we can see in year 2022 the yoy growth is 6.60% which is maximum among all other years
F94: possible reasons
F95: 1-Russia–Ukraine War
F96: 2-High Fuel Prices
F97: 3-Global Supply Chain Disruptions
...

Sheet All_India_Index_Upto_April23 (1
A1: Sector | B1: Year | C1: Month | D1: Year-month | E1: Cereals and products | F1: Meat and fish | G1: Egg | H1: Milk and products | I1: Oils and fats | J1: Fruits | K1: Vegetables | L1: Pulses and products | M1: Sugar and Confectionery | N1: Spices | O1: Non-alcoholic beverages | P1: Prepared meals, snacks, sweets etc. | Q1: Food and beverages | R1: MOM for Food nad beverages | S1: Pan, tobacco and intoxicants | T1: MOM for Pan,etc | U1: Clothing | V1: Footwear | W1: Clothing and footwear | X1: MOM for Clothing and Footwear | Y1: Housing | Z1: Fuel and light | AA1: MOM for Fuel and Light | AB1: Household goods and services | AC1: MOM for Household Goods and etc | AD1: Health | AE1: MOM for Health | AF1: Transport and communication | AG1: MOM for Transport and etc | AH1: Recreation and amusement | AI1: MOM for recreation and amusement | AJ1: Education | AK1: MOM for eduction | AL1: Personal care and effects | AM1: MOM for Personal care and effect | AN1: Miscellaneous | AO1: MOM for Miscellinous | AP1: General index | AQ1: MOM for Genral index
A2: Rural | B2: 2013 | C2: January | D2: =DATE(B2,MATCH(TRIM(C2),{"January","February","March","April","May","June","July","August","September","October","November","December"},0),1) -> 41275 | E2: 107.5 | F2: 106.3 | G2: 108.1 | H2: 104.9 | I2: 106.1 | J2: 103.9 | K2: 101.9 | L2: 106.1 | M2: 106.8 | N2: 103.1 | O2: 104.8 | P2: 106.7 | Q2: 105.5 | S2: 105.1 | U2: 106.5 | V2: 105.8 | W2: 106.4 | Y2: NA | Z2: 105.5 | AB2: 104.8 | AD2: 104 | AF2: 103.3 | AH2: 103.4 | AJ2: 103.8 | AL2: 104.7 | AN2: 104 | AP2: 105.1
A3: Urban | B3: 2013 | C3: January | D3: =DATE(B3,MATCH(TRIM(C3),{"January","February","March","April","May","June","July","August","September","October","November","December"},0),1) -> 41275 | E3: 110.5 | F3: 109.1 | G3: 113 | H3: 103.6 | I3: 103.4 | J3: 102.3 | K3: 102.9 | L3: 105.8 | M3: 105.1 | N3: 101.8 | O3: 105.1 | P3: 107.9 | Q3: 105.9 | S3: 105.2 | U3: 105.9 | V3: 105 | W3: 105.8 | Y3: 100.3 | Z3: 105.4 | AB3: 104.8 | AD3: 104.1 | AF3: 103.2 | AH3: 102.9 | AJ3: 103.5 | AL3: 104.3 | AN3: 103.7 | AP3: 104
A4: Rural+Urban | B4: 2013 | C4: January | D4: =DATE(B4,MATCH(TRIM(C4),{"January","February","March","April","May","June","July","August","September","October","November","December"},0),1) -> 41275 | E4: 108.4 | F4: 107.3 | G4: 110 | H4: 104.4 | I4: 105.1 | J4: 103.2 | K4: 102.2 | L4: 106 | M4: 106.2 | N4: 102.7 | O4: 104.9 | P4: 107.3 | Q4: 105.6 | S4: 105.1 | U4: 106.3 | V4: 105.5 | W4: 106.2 | Y4: 100.3 | Z4: 105.5 | AB4: 104.8 | AD4: 104 | AF4: 103.2 | AH4: 103.1 | AJ4: 103.6 | AL4: 104.5 | AN4: 103.9 | AP4: 104.6
A5: Rural | B5: 2013 | C5: February | D5: =DATE(B5,MATCH(TRIM(C5),{"January","February","March","April","May","June","July","August","September","October","November","December"},0),1) -> 41306 | E5: 109.2 | F5: 108.7 | G5: 110.2 | H5: 105.4 | I5: 106.7 | J5: 104 | K5: 102.4 | L5: 105.9 | M5: 105.7 | N5: 103.1 | O5: 105.1 | P5: 107.7 | Q5: 106.3 | S5: 105.6 | U5: 107.1 | V5: 106.3 | W5: 107 | Y5: NA | Z5: 106.2 | AB5: 105.2 | AD5: 104.4 | AF5: 103.9 | AH5: 104 | AJ5: 104.1 | AL5: 104.6 | AN5: 104.4 | AP5: 105.8
A6: Urban | B6: 2013 | C6: February | D6: =DATE(B6,MATCH(TRIM(C6),{"January","February","March","April","May","June","July","August","September","October","November","December"},0),1) -> 41306 | E6: 112.9 | F6: 112.9 | G6: 116.9 | H6: 104 | I6: 103.5 | J6: 103.1 | K6: 104.9 | L6: 104.1 | M6: 103.8 | N6: 102.3 | O6: 106 | P6: 109 | Q6: 107.2 | S6: 106 | U6: 106.6 | V6: 105.5 | W6: 106.4 | Y6: 100.4 | Z6: 105.7 | AB6: 105.2 | AD6: 104.7 | AF6: 104.4 | AH6: 103.3 | AJ6: 103.7 | AL6: 104.3 | AN6: 104.3 | AP6: 104.7
A7: Rural+Urban | B7: 2013 | C7: February | D7: =DATE(B7,MATCH(TRIM(C7),{"January","February","March","April","May","June","July","August","September","October","November","December"},0),1) -> 41306 | E7: 110.4 | F7: 110.2 | G7: 112.8 | H7: 104.9 | I7: 105.5 | J7: 103.6 | K7: 103.2 | L7: 105.3 | M7: 105.1 | N7: 102.8 | O7: 105.5 | P7: 108.3 | Q7: 106.6 | S7: 105.7 | U7: 106.9 | V7: 106 | W7: 106.8 | Y7: 100.4 | Z7: 106 | AB7: 105.2 | AD7: 104.5 | AF7: 104.2 | AH7: 103.6 | AJ7: 103.9 | AL7: 104.5 | AN7: 104.4 | AP7: 105.3
A8: Rural | B8: 2013 | C8: March | D8: =DATE(B8,MATCH(TRIM(C8),{"January","February","March","April","May","June","July","August","September","October","November","December"},0),1) -> 41334 | E8: 110.2 | F8: 108.8 | G8: 109.9 | H8: 105.6 | I8: 106.2 | J8: 105.7 | K8: 101.4 | L8: 105.7 | M8: 105 | N8: 103.3 | O8: 105.6 | P8: 108.2 | Q8: 106.6 | S8: 106.5 | U8: 107.6 | V8: 106.8 | W8: 107.5 | Y8: NA | Z8: 106.1 | AB8: 105.6 | AD8: 104.7 | AF8: 104.6 | AH8: 104 | AJ8: 104.3 | AL8: 104.3 | AN8: 104.6 | AP8: 106
A9: Urban | B9: 2013 | C9: March | D9: =DATE(B9,MATCH(TRIM(C9),{"January","February","March","April","May","June","July","August","September","October","November","December"},0),1) -> 41334 | E9: 113.9 | F9: 111.4 | G9: 113.2 | H9: 104.3 | I9: 102.7 | J9: 104.9 | K9: 103.8 | L9: 103.5 | M9: 102.6 | N9: 102.4 | O9: 107 | P9: 109.8 | Q9: 107.3 | S9: 106.8 | U9: 107.2 | V9: 106 | W9: 107 | Y9: 100.4 | Z9: 106 | AB9: 105.7 | AD9: 105.2 | AF9: 105.5 | AH9: 103.5 | AJ9: 103.8 | AL9: 104.2 | AN9: 104.9 | AP9: 105
A10: Rural+Urban | B10: 2013 | C10: March | D10: =DATE(B10,MATCH(TRIM(C10),{"January","February","March","April","May","June","July","August","September","October","November","December"},0),1) -> 41334 | E10: 111.4 | F10: 109.7 | G10: 111.2 | H10: 105.1 | I10: 104.9 | J10: 105.3 | K10: 102.2 | L10: 105 | M10: 104.2 | N10: 103 | O10: 106.2 | P10: 108.9 | Q10: 106.9 | S10: 106.6 | U10: 107.4 | V10: 106.5 | W10: 107.3 | Y10: 100.4 | Z10: 106.1 | AB10: 105.6 | AD10: 104.9 | AF10: 105.1 | AH10: 103.7 | AJ10: 104 | AL10: 104.3 | AN10: 104.7 | AP10: 105.5
A11: Rural | B11: 2013 | C11: April | D11: =DATE(B11,MATCH(TRIM(C11),{"January","February","March","April","May","June","July","August","September","October","November","December"},0),1) -> 41365 | E11: 110.2 | F11: 109.5 | G11: 106.9 | H11: 106.3 | I11: 105.7 | J11: 108.3 | K11: 103.4 | L11: 105.7 | M11: 104.2 | N11: 103.2 | O11: 106.5 | P11: 108.8 | Q11: 107.1 | S11: 107.1 | U11: 108.1 | V11: 107.4 | W11: 108 | Y11: NA | Z11: 106.5 | AB11: 106.1 | AD11: 105.1 | AF11: 104.4 | AH11: 104.5 | AJ11: 104.8 | AL11: 102.7 | AN11: 104.6 | AP11: 106.4
A12: Urban | B12: 2013 | C12: April | D12: =DATE(B12,MATCH(TRIM(C12),{"January","February","March","April","May","June","July","August","September","October","November","December"},0),1) -> 41365 | E12: 114.6 | F12: 113.4 | G12: 106 | H12: 104.7 | I12: 102.1 | J12: 109.5 | K12: 109.7 | L12: 104.6 | M12: 102 | N12: 103.5 | O12: 108.2 | P12: 110.6 | Q12: 108.8 | S12: 108.5 | U12: 107.9 | V12: 106.4 | W12: 107.7 | Y12: 100.5 | Z12: 106.4 | AB12: 106.5 | AD12: 105.7 | AF12: 105 | AH12: 104 | AJ12: 105.2 | AL12: 103.2 | AN12: 105.1 | AP12: 105.7
A13: Rural+Urban | B13: 2013 | C13: April | D13: =DATE(B13,MATCH(TRIM(C13),{"January","February","March","April","May","June","July","August","September","October","November","December"},0),1) -> 41365 | E13: 111.6 | F13: 110.9 | G13: 106.6 | H13: 105.7 | I13: 104.4 | J13: 108.9 | K13: 105.5 | L13: 105.3 | M13: 103.5 | N13: 103.3 | O13: 107.2 | P13: 109.6 | Q13: 107.7 | S13: 107.5 | U13: 108 | V13: 107 | W13: 107.9 | Y13: 100.5 | Z13: 106.5 | AB13: 106.3 | AD13: 105.3 | AF13: 104.7 | AH13: 104.2 | AJ13: 105 | AL13: 102.9 | AN13: 104.8 | AP13: 106.1
A14: Rural | B14: 2013 | C14: May | D14: =DATE(B14,MATCH(TRIM(C14),{"January","February","March","April","May","June","July","August","September","October","November","December"},0),1) -> 41395 | E14: 110.9 | F14: 109.8 | G14: 105.9 | H14: 107.5 | I14: 105.3 | J14: 108.1 | K14: 107.3 | L14: 106.1 | M14: 103.7 | N14: 104 | O14: 107.4 | P14: 109.9 | Q14: 108.1 | S14: 108.1 | U14: 108.8 | V14: 107.9 | W14: 108.6 | Y14: NA | Z14: 107.5 | AB14: 106.8 | AD14: 105.7 | AF14: 104.1 | AH14: 105 | AJ14: 105.5 | AL14: 102.1 | AN14: 104.8 | AP14: 107.2
A15: Urban | B15: 2013 | C15: May | D15: =DATE(B15,MATCH(TRIM(C15),{"January","February","March","April","May","June","July","August","September","October","November","December"},0),1) -> 41395 | E15: 115.4 | F15: 114.2 | G15: 102.7 | H15: 105.5 | I15: 101.5 | J15: 110.6 | K15: 123.7 | L15: 105.2 | M15: 101.9 | N15: 105 | O15: 109.1 | P15: 111.3 | Q15: 111.1 | S15: 109.8 | U15: 108.5 | V15: 106.7 | W15: 108.3 | Y15: 100.5 | Z15: 107.2 | AB15: 107.1 | AD15: 106.2 | AF15: 103.9 | AH15: 104.6 | AJ15: 105.7 | AL15: 102.6 | AN15: 104.9 | AP15: 106.6
A16: Rural+Urban | B16: 2013 | C16: May | D16: =DATE(B16,MATCH(TRIM(C16),{"January","February","March","April","May","June","July","August","September","October","November","December"},0),1) -> 41395 | E16: 112.3 | F16: 111.3 | G16: 104.7 | H16: 106.8 | I16: 103.9 | J16: 109.3 | K16: 112.9 | L16: 105.8 | M16: 103.1 | N16: 104.3 | O16: 108.1 | P16: 110.5 | Q16: 109.2 | S16: 108.6 | U16: 108.7 | V16: 107.4 | W16: 108.5 | Y16: 100.5 | Z16: 107.4 | AB16: 106.9 | AD16: 105.9 | AF16: 104 | AH16: 104.8 | AJ16: 105.6 | AL16: 102.3 | AN16: 104.8 | AP16: 106.9
A17: Rural | B17: 2013 | C17: June | D17: =DATE(B17,MATCH(TRIM(C17),{"January","February","March","April","May","June","July","August","September","October","November","December"},0),1) -> 41426 | E17: 112.3 | F17: 112.1 | G17: 108.1 | H17: 108.3 | I17: 105.9 | J17: 109.2 | K17: 118 | L17: 106.8 | M17: 104.1 | N17: 105.4 | O17: 108.2 | P17: 111 | Q17: 110.6 | S17: 109 | U17: 109.7 | V17: 108.8 | W17: 109.5 | Y17: NA | Z17: 108.5 | AB17: 107.5 | AD17: 106.3 | AF17: 105 | AH17: 105.6 | AJ17: 106.5 | AL17: 102.5 | AN17: 105.5 | AP17: 108.9
A18: Urban | B18: 2013 | C18: June | D18: =DATE(B18,MATCH(TRIM(C18),{"January","February","March","April","May","June","July","August","September","October","November","December"},0),1) -> 41426 | E18: 117 | F18: 120.1 | G18: 112.5 | H18: 107.3 | I18: 101.3 | J18: 112.4 | K18: 143.6 | L18: 105.4 | M18: 101.4 | N18: 106.4 | O18: 110 | P18: 112.2 | Q18: 115 | S18: 110.9 | U18: 109.2 | V18: 107.2 | W18: 108.9 | Y18: 106.6 | Z18: 108 | AB18: 107.7 | AD18: 106.5 | AF18: 105.2 | AH18: 105.2 | AJ18: 108.1 | AL18: 103.3 | AN18: 106.1 | AP18: 109.7
A19: Rural+Urban | B19: 2013 | C19: June | D19: =DATE(B19,MATCH(TRIM(C19),{"January","February","March","April","May","June","July","August","September","October","November","December"},0),1) -> 41426 | E19: 113.8 | F19: 114.9 | G19: 109.8 | H19: 107.9 | I19: 104.2 | J19: 110.7 | K19: 126.7 | L19: 106.3 | M19: 103.2 | N19: 105.7 | O19: 109 | P19: 111.6 | Q19: 112.2 | S19: 109.5 | U19: 109.5 | V19: 108.1 | W19: 109.3 | Y19: 106.6 | Z19: 108.3 | AB19: 107.6 | AD19: 106.4 | AF19: 105.1 | AH19: 105.4 | AJ19: 107.4 | AL19: 102.8 | AN19: 105.8 | AP19: 109.3
A20: Rural | B20: 2013 | C20: July | D20: =DATE(B20,MATCH(TRIM(C20),{"January","February","March","April","May","June","July","August","September","October","November","December"},0),1) -> 41456 | E20: 113.4 | F20: 114.9 | G20: 110.5 | H20: 109.3 | I20: 106.2 | J20: 110.3 | K20: 129.2 | L20: 107.1 | M20: 104.3 | N20: 106.4 | O20: 109.1 | P20: 112.1 | Q20: 113.1 | S20: 109.8 | U20: 110.5 | V20: 109.5 | W20: 110.3 | Y20: NA | Z20: 109.5 | AB20: 108.3 | AD20: 106.9 | AF20: 106.8 | AH20: 106.4 | AJ20: 107.8 | AL20: 102.5 | AN20: 106.5 | AP20: 110.7
A21: Urban | B21: 2013 | C21: July | D21: =DATE(B21,MATCH(TRIM(C21),{"January","February","March","April","May","June","July","August","September","October","November","December"},0),1) -> 41456 | E21: 117.8 | F21: 119.2 | G21: 114 | H21: 108.3 | I21: 101.1 | J21: 113.2 | K21: 160.9 | L21: 105.1 | M21: 101.3 | N21: 107.5 | O21: 110.4 | P21: 113.1 | Q21: 117.5 | S21: 111.7 | U21: 109.8 | V21: 107.8 | W21: 109.5 | Y21: 107.7 | Z21: 108.6 | AB21: 108.1 | AD21: 107.1 | AF21: 107.3 | AH21: 105.9 | AJ21: 110.1 | AL21: 103.2 | AN21: 107.3 | AP21: 111.4
A22: Rural+Urban | B22: 2013 | C22: July | D22: =DATE(B22,MATCH(TRIM(C22),{"January","February","March","April","May","June","July","August","September","October","November","December"},0),1) -> 41456 | E22: 114.8 | F22: 116.4 | G22: 111.9 | H22: 108.9 | I22: 104.3 | J22: 111.7 | K22: 140 | L22: 106.4 | M22: 103.3 | N22: 106.8 | O22: 109.6 | P22: 112.6 | Q22: 114.7 | S22: 110.3 | U22: 110.2 | V22: 108.8 | W22: 110 | Y22: 107.7 | Z22: 109.2 | AB22: 108.2 | AD22: 107 | AF22: 107.1 | AH22: 106.1 | AJ22: 109.1 | AL22: 102.8 | AN22: 106.9 | AP22: 111
A23: Rural | B23: 2013 | C23: August | D23: =DATE(B23,MATCH(TRIM(C23),{"January","February","March","April","May","June","July","August","September","October","November","December"},0),1) -> 41487 | E23: 114.3 | F23: 115.4 | G23: 111.1 | H23: 110 | I23: 106.4 | J23: 110.8 | K23: 138.9 | L23: 107.4 | M23: 104.1 | N23: 106.9 | O23: 109.7 | P23: 112.6 | Q23: 114.9 | S23: 110.7 | U23: 111.3 | V23: 110.2 | W23: 111.1 | Y23: NA | Z23: 109.9 | AB23: 108.7 | AD23: 107.5 | AF23: 107.8 | AH23: 106.8 | AJ23: 108.7 | AL23: 105 | AN23: 107.5 | AP23: 112.1
A24: Urban | B24: 2013 | C24: August | D24: =DATE(B24,MATCH(TRIM(C24),{"January","February","March","April","May","June","July","August","September","October","November","December"},0),1) -> 41487 | E24: 118.3 | F24: 120.4 | G24: 112.7 | H24: 108.9 | I24: 101.1 | J24: 108.7 | K24: 177 | L24: 104.7 | M24: 101 | N24: 108.5 | O24: 110.9 | P24: 114.3 | Q24: 119.6 | S24: 112.4 | U24: 110.6 | V24: 108.3 | W24: 110.2 | Y24: 108.9 | Z24: 109.3 | AB24: 108.7 | AD24: 107.6 | AF24: 108.1 | AH24: 106.5 | AJ24: 110.8 | AL24: 106 | AN24: 108.3 | AP24: 112.7
A25: Rural+Urban | B25: 2013 | C25: August | D25: =DATE(B25,MATCH(TRIM(C25),{"January","February","March","April","May","June","July","August","September","October","November","December"},0),1) -> 41487 | E25: 115.6 | F25: 117.2 | G25: 111.7 | H25: 109.6 | I25: 104.5 | J25: 109.8 | K25: 151.8 | L25: 106.5 | M25: 103.1 | N25: 107.4 | O25: 110.2 | P25: 113.4 | Q25: 116.6 | S25: 111.2 | U25: 111 | V25: 109.4 | W25: 110.7 | Y25: 108.9 | Z25: 109.7 | AB25: 108.7 | AD25: 107.5 | AF25: 108 | AH25: 106.6 | AJ25: 109.9 | AL25: 105.4 | AN25: 107.9 | AP25: 112.4
A26: Rural | B26: 2013 | C26: September | D26: =DATE(B26,MATCH(TRIM(C26),{"January","February","March","April","May","June","July","August","September","October","November","December"},0),1) -> 41518 | E26: 115.4 | F26: 115.7 | G26: 111.7 | H26: 111 | I26: 107.4 | J26: 110.9 | K26: 154 | L26: 108.1 | M26: 104.2 | N26: 107.9 | O26: 110.4 | P26: 114 | Q26: 117.8 | S26: 111.7 | U26: 112.7 | V26: 111.4 | W26: 112.5 | Y26: NA | Z26: 111.1 | AB26: 109.6 | AD26: 108.3 | AF26: 109.3 | AH26: 107.7 | AJ26: 109.8 | AL26: 106.7 | AN26: 108.7 | AP26: 114.2
A27: Urban | B27: 2013 | C27: September | D27: =DATE(B27,MATCH(TRIM(C27),{"January","February","March","April","May","June","July","August","September","October","November","December"},0),1) -> 41518 | E27: 118.6 | F27: 119.1 | G27: 113.2 | H27: 109.6 | I27: 101.7 | J27: 103.2 | K27: 174.3 | L27: 105.1 | M27: 100.8 | N27: 109.1 | O27: 111.1 | P27: 115.4 | Q27: 119.2 | S27: 112.9 | U27: 111.4 | V27: 109 | W27: 111.1 | Y27: 109.7 | Z27: 109.5 | AB27: 109.6 | AD27: 107.9 | AF27: 110.4 | AH27: 107.4 | AJ27: 111.2 | AL27: 106.9 | AN27: 109.4 | AP27: 113.2
A28: Rural+Urban | B28: 2013 | C28: September | D28: =DATE(B28,MATCH(TRIM(C28),{"January","February","March","April","May","June","July","August","September","October","November","December"},0),1) -> 41518 | E28: 116.4 | F28: 116.9 | G28: 112.3 | H28: 110.5 | I28: 105.3 | J28: 107.3 | K28: 160.9 | L28: 107.1 | M28: 103.1 | N28: 108.3 | O28: 110.7 | P28: 114.6 | Q28: 118.3 | S28: 112 | U28: 112.2 | V28: 110.4 | W28: 111.9 | Y28: 109.7 | Z28: 110.5 | AB28: 109.6 | AD28: 108.1 | AF28: 109.9 | AH28: 107.5 | AJ28: 110.6 | AL28: 106.8 | AN28: 109 | AP28: 113.7
A29: Rural | B29: 2013 | C29: October | D29: =DATE(B29,MATCH(TRIM(C29),{"January","February","March","April","May","June","July","August","September","October","November","December"},0),1) -> 41548 | E29: 116.3 | F29: 115.4 | G29: 112.6 | H29: 111.7 | I29: 107.7 | J29: 113.2 | K29: 164.9 | L29: 108.3 | M29: 103.9 | N29: 108.2 | O29: 111.1 | P29: 114.9 | Q29: 119.8 | S29: 112.2 | U29: 113.6 | V29: 112.3 | W29: 113.4 | Y29: NA | Z29: 111.6 | AB29: 110.4 | AD29: 108.9 | AF29: 109.3 | AH29: 108.3 | AJ29: 110.2 | AL29: 107.5 | AN29: 109.1 | AP29: 115.5
A30: Urban | B30: 2013 | C30: October | D30: =DATE(B30,MATCH(TRIM(C30),{"January","February","March","April","May","June","July","August","September","October","November","December"},0),1) -> 41548 | E30: 118.9 | F30: 118.1 | G30: 114.5 | H30: 110.4 | I30: 102.3 | J30: 106.2 | K30: 183.5 | L30: 105.3 | M30: 100.2 | N30: 109.6 | O30: 111.4 | P30: 116 | Q30: 120.8 | S30: 113.5 | U30: 112.5 | V30: 109.7 | W30: 112 | Y30: 110.5 | Z30: 109.7 | AB30: 110.2 | AD30: 108.2 | AF30: 109.7 | AH30: 108 | AJ30: 111.3 | AL30: 107.3 | AN30: 109.4 | AP30: 114
A31: Rural+Urban | B31: 2013 | C31: October | D31: =DATE(B31,MATCH(TRIM(C31),{"January","February","March","April","May","June","July","August","September","October","November","December"},0),1) -> 41548 | E31: 117.1 | F31: 116.3 | G31: 113.3 | H31: 111.2 | I31: 105.7 | J31: 109.9 | K31: 171.2 | L31: 107.3 | M31: 102.7 | N31: 108.7 | O31: 111.2 | P31: 115.4 | Q31: 120.2 | S31: 112.5 | U31: 113.2 | V31: 111.2 | W31: 112.8 | Y31: 110.5 | Z31: 110.9 | AB31: 110.3 | AD31: 108.6 | AF31: 109.5 | AH31: 108.1 | AJ31: 110.8 | AL31: 107.4 | AN31: 109.2 | AP31: 114.8
A32: Rural | B32: 2013 | C32: November | D32: =DATE(B32,MATCH(TRIM(C32),{"January","February","March","April","May","June","July","August","September","October","November","December"},0),1) -> 41579 | E32: 117.3 | F32: 114.9 | G32: 116.2 | H32: 112.8 | I32: 108.9 | J32: 116.6 | K32: 178.1 | L32: 109.1 | M32: 103.6 | N32: 109 | O32: 111.8 | P32: 116 | Q32: 122.5 | S32: 112.8 | U32: 114.6 | V32: 113.1 | W32: 114.4 | Y32: NA | Z32: 112.6 | AB32: 111.3 | AD32: 109.7 | AF32: 109.6 | AH32: 108.7 | AJ32: 111 | AL32: 108.2 | AN32: 109.8 | AP32: 117.4
A33: Urban | B33: 2013 | C33: November | D33: =DATE(B33,MATCH(TRIM(C33),{"January","February","March","April","May","June","July","August","September","October","November","December"},0),1) -> 41579 | E33: 119.8 | F33: 116.3 | G33: 122.6 | H33: 112 | I33: 103.2 | J33: 110 | K33: 192.8 | L33: 106.3 | M33: 99.5 | N33: 110.3 | O33: 111.8 | P33: 117.1 | Q33: 122.9 | S33: 114.1 | U33: 113.5 | V33: 110.3 | W33: 113 | Y33: 111.1 | Z33: 110 | AB33: 110.9 | AD33: 108.6 | AF33: 109.5 | AH33: 108.5 | AJ33: 111.3 | AL33: 107.9 | AN33: 109.6 | AP33: 115
A34: Rural+Urban | B34: 2013 | C34: November | D34: =DATE(B34,MATCH(TRIM(C34),{"January","February","March","April","May","June","July","August","September","October","November","December"},0),1) -> 41579 | E34: 118.1 | F34: 115.4 | G34: 118.7 | H34: 112.5 | I34: 106.8 | J34: 113.5 | K34: 183.1 | L34: 108.2 | M34: 102.2 | N34: 109.4 | O34: 111.8 | P34: 116.5 | Q34: 122.6 | S34: 113.1 | U34: 114.2 | V34: 111.9 | W34: 113.8 | Y34: 111.1 | Z34: 111.6 | AB34: 111.1 | AD34: 109.3 | AF34: 109.5 | AH34: 108.6 | AJ34: 111.2 | AL34: 108.1 | AN34: 109.7 | AP34: 116.3
A35: Rural | B35: 2013 | C35: December | D35: =DATE(B35,MATCH(TRIM(C35),{"January","February","March","April","May","June","July","August","September","October","November","December"},0),1) -> 41609 | E35: 118.4 | F35: 115.9 | G35: 120.4 | H35: 113.8 | I35: 109.5 | J35: 115.5 | K35: 145.7 | L35: 109.5 | M35: 102.9 | N35: 109.8 | O35: 112.1 | P35: 116.8 | Q35: 118.7 | S35: 113.6 | U35: 115.8 | V35: 114 | W35: 115.5 | Y35: NA | Z35: 112.8 | AB35: 112.1 | AD35: 110.1 | AF35: 109.9 | AH35: 109.2 | AJ35: 111.6 | AL35: 108.1 | AN35: 110.1 | AP35: 115.5
A36: Urban | B36: 2013 | C36: December | D36: =DATE(B36,MATCH(TRIM(C36),{"January","February","March","April","May","June","July","August","September","October","November","December"},0),1) -> 41609 | E36: 120.5 | F36: 118.1 | G36: 128.5 | H36: 112.8 | I36: 103.4 | J36: 110.7 | K36: 144.8 | L36: 107.1 | M36: 98.6 | N36: 111.9 | O36: 112.1 | P36: 118.1 | Q36: 117.8 | S36: 115 | U36: 114.2 | V36: 110.9 | W36: 113.7 | Y36: 110.7 | Z36: 110.4 | AB36: 111.3 | AD36: 109 | AF36: 109.7 | AH36: 108.9 | AJ36: 111.4 | AL36: 107.7 | AN36: 109.8 | AP36: 113.3
A37: Rural+Urban | B37: 2013 | C37: December | D37: =DATE(B37,MATCH(TRIM(C37),{"January","February","March","April","May","June","July","August","September","October","November","December"},0),1) -> 41609 | E37: 119.1 | F37: 116.7 | G37: 123.5 | H37: 113.4 | I37: 107.3 | J37: 113.3 | K37: 145.4 | L37: 108.7 | M37: 101.5 | N37: 110.5 | O37: 112.1 | P37: 117.4 | Q37: 118.4 | S37: 114 | U37: 115.2 | V37: 112.7 | W37: 114.8 | Y37: 110.7 | Z37: 111.9 | AB37: 111.7 | AD37: 109.7 | AF37: 109.8 | AH37: 109 | AJ37: 111.5 | AL37: 107.9 | AN37: 110 | AP37: 114.5
A38: Rural | B38: 2014 | C38: January | D38: =DATE(B38,MATCH(TRIM(C38),{"January","February","March","April","May","June","July","August","September","October","November","December"},0),1) -> 41640 | E38: 118.9 | F38: 117.1 | G38: 120.5 | H38: 114.4 | I38: 109 | J38: 115.5 | K38: 123.9 | L38: 109.6 | M38: 101.8 | N38: 110.2 | O38: 112.4 | P38: 117.3 | Q38: 116 | S38: 114 | U38: 116.5 | V38: 114.5 | W38: 116.2 | Y38: NA | Z38: 113 | AB38: 112.6 | AD38: 110.6 | AF38: 110.5 | AH38: 109.6 | AJ38: 111.8 | AL38: 108.3 | AN38: 110.6 | AP38: 114.2
A39: Urban | B39: 2014 | C39: January | D39: =DATE(B39,MATCH(TRIM(C39),{"January","February","March","April","May","June","July","August","September","October","November","December"},0),1) -> 41640 | E39: 121.2 | F39: 122 | G39: 129.9 | H39: 113.6 | I39: 102.9 | J39: 112.1 | K39: 118.9 | L39: 107.5 | M39: 96.9 | N39: 112.7 | O39: 112.1 | P39: 119 | Q39: 115.5 | S39: 115.7 | U39: 114.8 | V39: 111.3 | W39: 114.3 | Y39: 111.6 | Z39: 111 | AB39: 111.9 | AD39: 109.7 | AF39: 110.8 | AH39: 109.8 | AJ39: 111.5 | AL39: 108 | AN39: 110.5 | AP39: 112.9
A40: Rural+Urban | B40: 2014 | C40: January | D40: =DATE(B40,MATCH(TRIM(C40),{"January","February","March","April","May","June","July","August","September","October","November","December"},0),1) -> 41640 | E40: 119.6 | F40: 118.8 | G40: 124.1 | H40: 114.1 | I40: 106.8 | J40: 113.9 | K40: 122.2 | L40: 108.9 | M40: 100.2 | N40: 111 | O40: 112.3 | P40: 118.1 | Q40: 115.8 | S40: 114.5 | U40: 115.8 | V40: 113.2 | W40: 115.4 | Y40: 111.6 | Z40: 112.2 | AB40: 112.3 | AD40: 110.3 | AF40: 110.7 | AH40: 109.7 | AJ40: 111.6 | AL40: 108.2 | AN40: 110.6 | AP40: 113.6
...

Sheet Sheet5
A1: Sector | B1: Year | C1: Month | D1: Year-month | E1: Food and beverages | F1: MOM for Food nad beverages | G1: Pan, tobacco and intoxicants | H1: MOM for Pan,etc | I1: Clothing and footwear | J1: MOM for Clothing and Footwear | K1: Fuel and light | L1: MOM for Fuel and Light | M1: Household goods and services | N1: MOM for Household Goods and etc | O1: Health | P1: MOM for Health | Q1: Transport and communication | R1: MOM for Transport and etc | S1: Recreation and amusement | T1: MOM for recreation and amusement | U1: Education | V1: MOM for eduction | W1: Personal care and effects | X1: MOM for Personal care and effect | Y1: Miscellaneous | Z1: MOM for Miscellinous | AA1: General index | AB1: MOM for Genral index | AC1: Crude Oil | AD1: MOM of crude oil | AG1: broader categories | AH1: correltion
A2: Rural+Urban | B2: 2021 | C2: January | D2: 44197 | E2: 161 | G2: 186.5 | I2: 154.2 | K2: 147.9 | M2: 150 | O2: 159.3 | Q2: 141.9 | S2: 149.6 | U2: 159.2 | W2: 156.8 | Y2: 151.9 | AA2: 157.3 | AC2: =VLOOKUP(D2,'crude oil'!A1:E28,4,0) -> 54.79
A3: Rural+Urban | B3: 2021 | C3: February | D3: 44228 | E3: 156.9 | F3: =(E3-E2)/E2 -> -0.025465839 | G3: 188.3 | H3: =(G3-G2)/G2 -> 0.0096514745 | I3: 155.8 | J3: =(I3-I2)/I2 -> 0.010376135 | K3: 152.4 | L3: =(K3-K2)/K2 -> 0.030425963 | M3: 150.9 | N3: =(M3-M2)/M2 -> 0.006 | O3: 161.3 | P3: =(O3-O2)/O2 -> 0.012554928 | Q3: 145.1 | R3: =(Q3-Q2)/Q2 -> 0.022551092 | S3: 151.5 | T3: =(S3-S2)/S2 -> 0.012700535 | U3: 159.5 | V3: =(U3-U2)/U2 -> 0.0018844221 | W3: 155.8 | X3: =(W3-W2)/W2 -> -0.006377551 | Y3: 153.4 | Z3: =(Y3-Y2)/Y2 -> 0.0098749177 | AA3: 156.6 | AB3: =(AA3-AA2)/AA2 -> -0.0044500954 | AC3: =VLOOKUP(D3,'crude oil'!A2:E29,4,0) -> 61.22 | AD3: =VLOOKUP(D3,'crude oil'!A2:E29,5,0) -> 0.11735718 | AG3: Food and Beverages | AH3: =CORREL(F:F,AD:AD) -> 0.10939845
A4: Rural+Urban | B4: 2021 | C4: March | D4: 44256 | E4: 156.7 | F4: =(E4-E3)/E3 -> -0.0012746973 | G4: 188.1 | H4: =(G4-G3)/G3 -> -0.0010621349 | I4: 156.4 | J4: =(I4-I3)/I3 -> 0.0038510911 | K4: 155.5 | L4: =(K4-K3)/K3 -> 0.020341207 | M4: 151.2 | N4: =(M4-M3)/M3 -> 0.0019880716 | O4: 161.7 | P4: =(O4-O3)/O3 -> 0.0024798512 | Q4: 146.2 | R4: =(Q4-Q3)/Q3 -> 0.0075809786 | S4: 152.6 | T4: =(S4-S3)/S3 -> 0.0072607261 | U4: 160.2 | V4: =(U4-U3)/U3 -> 0.0043887147 | W4: 153.8 | X4: =(W4-W3)/W3 -> -0.01283697 | Y4: 153.8 | Z4: =(Y4-Y3)/Y3 -> 0.0026075619 | AA4: 156.8 | AB4: =(AA4-AA3)/AA3 -> 0.0012771392 | AC4: =VLOOKUP(D4,'crude oil'!A3:E30,4,0) -> 64.73 | AD4: =VLOOKUP(D4,'crude oil'!A3:E30,5,0) -> 0.057334205 | AG4: Pan, Tobacco and Intoxicants | AH4: =CORREL(H:H,AD:AD) -> 0.13968414
A5: Rural+Urban | B5: 2021 | C5: April | D5: 44287 | E5: 158 | F5: =(E5-E4)/E4 -> 0.0082961072 | G5: 188.8 | H5: =(G5-G4)/G4 -> 0.0037214248 | I5: 157.3 | J5: =(I5-I4)/I4 -> 0.0057544757 | K5: 155.6 | L5: =(K5-K4)/K4 -> 0.00064308682 | M5: 151.8 | N5: =(M5-M4)/M4 -> 0.003968254 | O5: 162.3 | P5: =(O5-O4)/O4 -> 0.0037105751 | Q5: 146.6 | R5: =(Q5-Q4)/Q4 -> 0.0027359781 | S5: 153.2 | T5: =(S5-S4)/S4 -> 0.003931848 | U5: 160.3 | V5: =(U5-U4)/U4 -> 0.00062421973 | W5: 155.4 | X5: =(W5-W4)/W4 -> 0.010403121 | Y5: 154.4 | Z5: =(Y5-Y4)/Y4 -> 0.0039011704 | AA5: 157.8 | AB5: =(AA5-AA4)/AA4 -> 0.006377551 | AC5: =VLOOKUP(D5,'crude oil'!A4:E31,4,0) -> 63.4 | AD5: =VLOOKUP(D5,'crude oil'!A4:E31,5,0) -> -0.020546887 | AG5: Clothing and Footwear | AH5: =CORREL(J:J,AD:AD) -> 0.10496857
A6: Rural+Urban | B6: 2021 | C6: May | D6: 44317 | E6: 160.7 | F6: =(E6-E5)/E5 -> 0.017088608 | G6: 191.9 | H6: =(G6-G5)/G5 -> 0.016419492 | I6: 160.4 | J6: =(I6-I5)/I5 -> 0.019707565 | K6: 159.4 | L6: =(K6-K5)/K5 -> 0.024421594 | M6: 154.7 | N6: =(M6-M5)/M5 -> 0.019104084 | O6: 165.8 | P6: =(O6-O5)/O5 -> 0.021565003 | Q6: 148.9 | R6: =(Q6-Q5)/Q5 -> 0.01568895 | S6: 155.8 | T6: =(S6-S5)/S5 -> 0.016971279 | U6: 161.2 | V6: =(U6-U5)/U5 -> 0.0056144729 | W6: 158.6 | X6: =(W6-W5)/W5 -> 0.020592021 | Y6: 156.8 | Z6: =(Y6-Y5)/Y5 -> 0.015544041 | AA6: 160.4 | AB6: =(AA6-AA5)/AA5 -> 0.016476553 | AC6: =VLOOKUP(D6,'crude oil'!A5:E32,4,0) -> 66.95 | AD6: =VLOOKUP(D6,'crude oil'!A5:E32,5,0) -> 0.055993691 | AG6: Fuel and Light | AH6: =CORREL(L:L,AD:AD) -> 0.13261758
A7: Rural+Urban | B7: 2021 | C7: June | D7: 44348 | E7: 162.6 | F7: =(E7-E6)/E6 -> 0.011823273 | G7: 190.8 | H7: =(G7-G6)/G6 -> -0.0057321522 | I7: 160.7 | J7: =(I7-I6)/I6 -> 0.0018703242 | K7: 159.8 | L7: =(K7-K6)/K6 -> 0.0025094103 | M7: 154.8 | N7: =(M7-M6)/M6 -> 0.00064641241 | O7: 166.3 | P7: =(O7-O6)/O6 -> 0.0030156815 | Q7: 150.7 | R7: =(Q7-Q6)/Q6 -> 0.01208865 | S7: 154.9 | T7: =(S7-S6)/S6 -> -0.0057766367 | U7: 161.7 | V7: =(U7-U6)/U6 -> 0.003101737 | W7: 158.8 | X7: =(W7-W6)/W6 -> 0.001261034 | Y7: 157.6 | Z7: =(Y7-Y6)/Y6 -> 0.0051020408 | AA7: 161.3 | AB7: =(AA7-AA6)/AA6 -> 0.0056109726 | AC7: =VLOOKUP(D7,'crude oil'!A6:E33,4,0) -> 71.98 | AD7: =VLOOKUP(D7,'crude oil'!A6:E33,5,0) -> 0.075130695 | AG7: Household Goods and Services | AH7: =CORREL(N:N,AD:AD) -> -0.004421401
A8: Rural+Urban | B8: 2021 | C8: July | D8: 44378 | E8: 164 | F8: =(E8-E7)/E7 -> 0.0086100861 | G8: 191.2 | H8: =(G8-G7)/G7 -> 0.0020964361 | I8: 161.4 | J8: =(I8-I7)/I7 -> 0.0043559428 | K8: 160.7 | L8: =(K8-K7)/K7 -> 0.0056320401 | M8: 155.8 | N8: =(M8-M7)/M7 -> 0.0064599483 | O8: 167 | P8: =(O8-O7)/O7 -> 0.0042092604 | Q8: 153.1 | R8: =(Q8-Q7)/Q7 -> 0.01592568 | S8: 155.3 | T8: =(S8-S7)/S7 -> 0.0025823112 | U8: 163.2 | V8: =(U8-U7)/U7 -> 0.0092764378 | W8: 160.1 | X8: =(W8-W7)/W7 -> 0.008186398 | Y8: 159 | Z8: =(Y8-Y7)/Y7 -> 0.0088832487 | AA8: 162.5 | AB8: =(AA8-AA7)/AA7 -> 0.0074395536 | AC8: =VLOOKUP(D8,'crude oil'!A7:E34,4,0) -> 73.54 | AD8: =VLOOKUP(D8,'crude oil'!A7:E34,5,0) -> 0.021672687 | AG8: Health | AH8: =CORREL(P:P,AD:AD) -> 0.077797237
A9: Rural+Urban | B9: 2021 | C9: August | D9: 44409 | E9: 164 | F9: =(E9-E8)/E8 -> 0 | G9: 192.1 | H9: =(G9-G8)/G8 -> 0.004707113 | I9: 163.2 | J9: =(I9-I8)/I8 -> 0.011152416 | K9: 162.6 | L9: =(K9-K8)/K8 -> 0.011823273 | M9: 157.5 | N9: =(M9-M8)/M8 -> 0.010911425 | O9: 168.4 | P9: =(O9-O8)/O8 -> 0.0083832335 | Q9: 154 | R9: =(Q9-Q8)/Q8 -> 0.0058785108 | S9: 157.6 | T9: =(S9-S8)/S8 -> 0.014810045 | U9: 163.8 | V9: =(U9-U8)/U8 -> 0.0036764706 | W9: 160 | X9: =(W9-W8)/W8 -> -0.00062460962 | Y9: 160 | Z9: =(Y9-Y8)/Y8 -> 0.0062893082 | AA9: 163.2 | AB9: =(AA9-AA8)/AA8 -> 0.0043076923 | AC9: =VLOOKUP(D9,'crude oil'!A8:E35,4,0) -> 69.8 | AD9: =VLOOKUP(D9,'crude oil'!A8:E35,5,0) -> -0.050856677 | AG9: Transport and Communication | AH9: =CORREL(R:R,AD:AD) -> 0.097696081
A10: Rural+Urban | B10: 2021 | C10: September | D10: 44440 | E10: 164 | F10: =(E10-E9)/E9 -> 0 | G10: 192.1 | H10: =(G10-G9)/G9 -> 0 | I10: 163.3 | J10: =(I10-I9)/I9 -> 0.0006127451 | K10: 162.6 | L10: =(K10-K9)/K9 -> 0 | M10: 157.5 | N10: =(M10-M9)/M9 -> 0 | O10: 168.4 | P10: =(O10-O9)/O9 -> 0 | Q10: 154 | R10: =(Q10-Q9)/Q9 -> 0 | S10: 157.7 | T10: =(S10-S9)/S9 -> 0.00063451777 | U10: 163.7 | V10: =(U10-U9)/U9 -> -0.00061050061 | W10: 160 | X10: =(W10-W9)/W9 -> 0 | Y10: 160 | Z10: =(Y10-Y9)/Y9 -> 0 | AA10: 163.2 | AB10: =(AA10-AA9)/AA9 -> 0 | AC10: =VLOOKUP(D10,'crude oil'!A9:E36,4,0) -> 73.13 | AD10: =VLOOKUP(D10,'crude oil'!A9:E36,5,0) -> 0.047707736 | AG10: Recreation and Amusement | AH10: =CORREL(T:T,AD:AD) -> 0.12837906
A11: Rural+Urban | B11: 2021 | C11: October | D11: 44470 | E11: 167.7 | F11: =(E11-E10)/E10 -> 0.022560976 | G11: 192.7 | H11: =(G11-G10)/G10 -> 0.0031233732 | I11: 164.3 | J11: =(I11-I10)/I10 -> 0.0061236987 | K11: 164.2 | L11: =(K11-K10)/K10 -> 0.0098400984 | M11: 158.4 | N11: =(M11-M10)/M10 -> 0.0057142857 | O11: 169.1 | P11: =(O11-O10)/O10 -> 0.0041567696 | Q11: 155.7 | R11: =(Q11-Q10)/Q10 -> 0.011038961 | S11: 158.6 | T11: =(S11-S10)/S10 -> 0.0057070387 | U11: 163.9 | V11: =(U11-U10)/U10 -> 0.0012217471 | W11: 160.8 | X11: =(W11-W10)/W10 -> 0.005 | Y11: 161 | Z11: =(Y11-Y10)/Y10 -> 0.00625 | AA11: 165.5 | AB11: =(AA11-AA10)/AA10 -> 0.014093137 | AC11: =VLOOKUP(D11,'crude oil'!A10:E37,4,0) -> 82.11 | AD11: =VLOOKUP(D11,'crude oil'!A10:E37,5,0) -> 0.12279502 | AG11: Education | AH11: =CORREL(V:V,AD:AD) -> -0.15568221
A12: Rural+Urban | B12: 2021 | C12: November | D12: 44501 | E12: 169.7 | F12: =(E12-E11)/E11 -> 0.011926058 | G12: 192.9 | H12: =(G12-G11)/G11 -> 0.0010378827 | I12: 165.8 | J12: =(I12-I11)/I11 -> 0.0091296409 | K12: 163.9 | L12: =(K12-K11)/K11 -> -0.0018270402 | M12: 159.3 | N12: =(M12-M11)/M11 -> 0.0056818182 | O12: 169.9 | P12: =(O12-O11)/O11 -> 0.0047309284 | Q12: 154.8 | R12: =(Q12-Q11)/Q11 -> -0.0057803468 | S12: 159.8 | T12: =(S12-S11)/S11 -> 0.0075662043 | U12: 164.3 | V12: =(U12-U11)/U11 -> 0.0024405125 | W12: 162.2 | X12: =(W12-W11)/W11 -> 0.0087064677 | Y12: 161.4 | Z12: =(Y12-Y11)/Y11 -> 0.002484472 | AA12: 166.7 | AB12: =(AA12-AA11)/AA11 -> 0.0072507553 | AC12: =VLOOKUP(D12,'crude oil'!A11:E38,4,0) -> 80.64 | AD12: =VLOOKUP(D12,'crude oil'!A11:E38,5,0) -> -0.017902813 | AG12: Personal Care and Effects | AH12: =CORREL(X:X,AD:AD) -> -3.7153546e-05
A13: Rural+Urban | B13: 2021 | C13: December | D13: 44531 | E13: 168.2 | F13: =(E13-E12)/E12 -> -0.0088391279 | G13: 192.4 | H13: =(G13-G12)/G12 -> -0.0025920166 | I13: 167 | J13: =(I13-I12)/I12 -> 0.0072376357 | K13: 164.1 | L13: =(K13-K12)/K12 -> 0.0012202563 | M13: 160.2 | N13: =(M13-M12)/M12 -> 0.0056497175 | O13: 170.6 | P13: =(O13-O12)/O12 -> 0.0041200706 | Q13: 155.7 | R13: =(Q13-Q12)/Q12 -> 0.0058139535 | S13: 160.6 | T13: =(S13-S12)/S12 -> 0.0050062578 | U13: 164.4 | V13: =(U13-U12)/U12 -> 0.00060864273 | W13: 162.6 | X13: =(W13-W12)/W12 -> 0.0024660912 | Y13: 162 | Z13: =(Y13-Y12)/Y12 -> 0.0037174721 | AA13: 166.2 | AB13: =(AA13-AA12)/AA12 -> -0.0029994001 | AC13: =VLOOKUP(D13,'crude oil'!A12:E39,4,0) -> 73.3 | AD13: =VLOOKUP(D13,'crude oil'!A12:E39,5,0) -> -0.091021825 | AG13: Miscellaneous | AH13: =CORREL(Z:Z,AD:AD) -> 0.079750052
A14: Rural+Urban | B14: 2022 | C14: January | D14: 44562 | E14: 166.4 | F14: =(E14-E13)/E13 -> -0.010701546 | G14: 192.2 | H14: =(G14-G13)/G13 -> -0.001039501 | I14: 168.5 | J14: =(I14-I13)/I13 -> 0.0089820359 | K14: 164.2 | L14: =(K14-K13)/K13 -> 0.00060938452 | M14: 161.1 | N14: =(M14-M13)/M13 -> 0.0056179775 | O14: 171.4 | P14: =(O14-O13)/O13 -> 0.0046893318 | Q14: 156.5 | R14: =(Q14-Q13)/Q13 -> 0.0051380861 | S14: 161.2 | T14: =(S14-S13)/S13 -> 0.00373599 | U14: 164.7 | V14: =(U14-U13)/U13 -> 0.0018248175 | W14: 163 | X14: =(W14-W13)/W13 -> 0.0024600246 | Y14: 162.7 | Z14: =(Y14-Y13)/Y13 -> 0.0043209877 | AA14: 165.7 | AB14: =(AA14-AA13)/AA13 -> -0.0030084236 | AC14: =VLOOKUP(D14,'crude oil'!A13:E40,4,0) -> 84.67 | AD14: =VLOOKUP(D14,'crude oil'!A13:E40,5,0) -> 0.15511596 | AG14: General Index | AH14: =CORREL(AB:AB,AD:AD) -> 0.13192465
A15: Rural+Urban | B15: 2022 | C15: February | D15: 44593 | E15: 166.2 | F15: =(E15-E14)/E14 -> -0.0012019231 | G15: 192.8 | H15: =(G15-G14)/G14 -> 0.0031217482 | I15: 169.6 | J15: =(I15-I14)/I14 -> 0.0065281899 | K15: 165.7 | L15: =(K15-K14)/K14 -> 0.009135201 | M15: 161.8 | N15: =(M15-M14)/M14 -> 0.0043451273 | O15: 172.2 | P15: =(O15-O14)/O14 -> 0.0046674446 | Q15: 156.9 | R15: =(Q15-Q14)/Q14 -> 0.0025559105 | S15: 162.1 | T15: =(S15-S14)/S14 -> 0.0055831266 | U15: 165.4 | V15: =(U15-U14)/U14 -> 0.0042501518 | W15: 164.4 | X15: =(W15-W14)/W14 -> 0.0085889571 | Y15: 163.5 | Z15: =(Y15-Y14)/Y14 -> 0.0049170252 | AA15: 166.1 | AB15: =(AA15-AA14)/AA14 -> 0.0024140012 | AC15: =VLOOKUP(D15,'crude oil'!A14:E41,4,0) -> 94.07 | AD15: =VLOOKUP(D15,'crude oil'!A14:E41,5,0) -> 0.11101925
A16: Rural+Urban | B16: 2022 | C16: March | D16: 44621 | E16: 168.4 | F16: =(E16-E15)/E15 -> 0.013237064 | G16: 193.7 | H16: =(G16-G15)/G15 -> 0.0046680498 | I16: 171.1 | J16: =(I16-I15)/I15 -> 0.0088443396 | K16: 167.2 | L16: =(K16-K15)/K15 -> 0.0090525045 | M16: 162.8 | N16: =(M16-M15)/M15 -> 0.0061804697 | O16: 173 | P16: =(O16-O15)/O15 -> 0.0046457607 | Q16: 157.9 | R16: =(Q16-Q15)/Q15 -> 0.0063734863 | S16: 163.3 | T16: =(S16-S15)/S15 -> 0.0074028378 | U16: 166 | V16: =(U16-U15)/U15 -> 0.0036275695 | W16: 167.2 | X16: =(W16-W15)/W15 -> 0.01703163 | Y16: 164.6 | Z16: =(Y16-Y15)/Y15 -> 0.0067278287 | AA16: 167.7 | AB16: =(AA16-AA15)/AA15 -> 0.0096327514 | AC16: =VLOOKUP(D16,'crude oil'!A15:E42,4,0) -> 112.87 | AD16: =VLOOKUP(D16,'crude oil'!A15:E42,5,0) -> 0.19985117
A17: Rural+Urban | B17: 2022 | C17: April | D17: 44652 | E17: 170.8 | F17: =(E17-E16)/E16 -> 0.014251781 | G17: 193.9 | H17: =(G17-G16)/G16 -> 0.0010325245 | I17: 172.8 | J17: =(I17-I16)/I16 -> 0.0099357101 | K17: 172.2 | L17: =(K17-K16)/K16 -> 0.029904306 | M17: 164 | N17: =(M17-M16)/M16 -> 0.0073710074 | O17: 174 | P17: =(O17-O16)/O16 -> 0.0057803468 | Q17: 162.6 | R17: =(Q17-Q16)/Q16 -> 0.029765674 | S17: 164.4 | T17: =(S17-S16)/S16 -> 0.0067360686 | U17: 166.9 | V17: =(U17-U16)/U16 -> 0.0054216867 | W17: 168.8 | X17: =(W17-W16)/W16 -> 0.009569378 | Y17: 166.8 | Z17: =(Y17-Y16)/Y16 -> 0.013365735 | AA17: 170.1 | AB17: =(AA17-AA16)/AA16 -> 0.01431127 | AC17: =VLOOKUP(D17,'crude oil'!A16:E43,4,0) -> 102.97 | AD17: =VLOOKUP(D17,'crude oil'!A16:E43,5,0) -> -0.087711527
A18: Rural+Urban | B18: 2022 | C18: May | D18: 44682 | E18: 173.3 | F18: =(E18-E17)/E17 -> 0.014637002 | G18: 194.1 | H18: =(G18-G17)/G17 -> 0.0010314595 | I18: 174.6 | J18: =(I18-I17)/I17 -> 0.010416667 | K18: 174.6 | L18: =(K18-K17)/K17 -> 0.013937282 | M18: 165.2 | N18: =(M18-M17)/M17 -> 0.0073170732 | O18: 174.8 | P18: =(O18-O17)/O17 -> 0.0045977011 | Q18: 163 | R18: =(Q18-Q17)/Q17 -> 0.0024600246 | S18: 165.1 | T18: =(S18-S17)/S17 -> 0.0042579075 | U18: 167.9 | V18: =(U18-U17)/U17 -> 0.0059916117 | W18: 168.4 | X18: =(W18-W17)/W17 -> -0.0023696682 | Y18: 167.5 | Z18: =(Y18-Y17)/Y17 -> 0.0041966427 | AA18: 171.7 | AB18: =(AA18-AA17)/AA17 -> 0.0094062316 | AC18: =VLOOKUP(D18,'crude oil'!A17:E44,4,0) -> 109.51 | AD18: =VLOOKUP(D18,'crude oil'!A17:E44,5,0) -> 0.063513645
A19: Rural+Urban | B19: 2022 | C19: June | D19: 44713 | E19: 174.9 | F19: =(E19-E18)/E18 -> 0.0092325447 | G19: 194.3 | H19: =(G19-G18)/G18 -> 0.0010303967 | I19: 176 | J19: =(I19-I18)/I18 -> 0.0080183276 | K19: 176 | L19: =(K19-K18)/K18 -> 0.0080183276 | M19: 166.4 | N19: =(M19-M18)/M18 -> 0.0072639225 | O19: 175.4 | P19: =(O19-O18)/O18 -> 0.0034324943 | Q19: 161.1 | R19: =(Q19-Q18)/Q18 -> -0.011656442 | S19: 165.8 | T19: =(S19-S18)/S18 -> 0.0042398546 | U19: 169 | V19: =(U19-U18)/U18 -> 0.0065515188 | W19: 169.4 | X19: =(W19-W18)/W18 -> 0.0059382423 | Y19: 167.5 | Z19: =(Y19-Y18)/Y18 -> 0 | AA19: 172.6 | AB19: =(AA19-AA18)/AA18 -> 0.0052417006 | AC19: =VLOOKUP(D19,'crude oil'!A18:E45,4,0) -> 116.01 | AD19: =VLOOKUP(D19,'crude oil'!A18:E45,5,0) -> 0.05935531
A20: Rural+Urban | B20: 2022 | C20: July | D20: 44743 | E20: 175 | F20: =(E20-E19)/E19 -> 0.00057175529 | G20: 194.6 | H20: =(G20-G19)/G19 -> 0.0015440041 | I20: 177.3 | J20: =(I20-I19)/I19 -> 0.0073863636 | K20: 179.6 | L20: =(K20-K19)/K19 -> 0.020454545 | M20: 167.4 | N20: =(M20-M19)/M19 -> 0.0060096154 | O20: 176.1 | P20: =(O20-O19)/O19 -> 0.003990878 | Q20: 161.6 | R20: =(Q20-Q19)/Q19 -> 0.0031036623 | S20: 166.3 | T20: =(S20-S19)/S19 -> 0.0030156815 | U20: 171.4 | V20: =(U20-U19)/U19 -> 0.014201183 | W20: 169.7 | X20: =(W20-W19)/W19 -> 0.0017709563 | Y20: 168.4 | Z20: =(Y20-Y19)/Y19 -> 0.0053731343 | AA20: 173.4 | AB20: =(AA20-AA19)/AA19 -> 0.0046349942 | AC20: =VLOOKUP(D20,'crude oil'!A19:E46,4,0) -> 105.49 | AD20: =VLOOKUP(D20,'crude oil'!A19:E46,5,0) -> -0.090681838
A21: Rural+Urban | B21: 2022 | C21: August | D21: 44774 | E21: 176.3 | F21: =(E21-E20)/E20 -> 0.0074285714 | G21: 195 | H21: =(G21-G20)/G20 -> 0.0020554985 | I21: 178.5 | J21: =(I21-I20)/I20 -> 0.0067681895 | K21: 178.8 | L21: =(K21-K20)/K20 -> -0.004454343 | M21: 168.5 | N21: =(M21-M20)/M20 -> 0.0065710872 | O21: 176.8 | P21: =(O21-O20)/O20 -> 0.0039750142 | Q21: 161.9 | R21: =(Q21-Q20)/Q20 -> 0.0018564356 | S21: 166.9 | T21: =(S21-S20)/S20 -> 0.0036079375 | U21: 172.3 | V21: =(U21-U20)/U20 -> 0.0052508751 | W21: 171.2 | X21: =(W21-W20)/W20 -> 0.0088391279 | Y21: 169.1 | Z21: =(Y21-Y20)/Y20 -> 0.0041567696 | AA21: 174.3 | AB21: =(AA21-AA20)/AA20 -> 0.0051903114 | AC21: =VLOOKUP(D21,'crude oil'!A20:E47,4,0) -> 97.4 | AD21: =VLOOKUP(D21,'crude oil'!A20:E47,5,0) -> -0.076689734
A22: Rural+Urban | B22: 2022 | C22: September | D22: 44805 | E22: 177.8 | F22: =(E22-E21)/E21 -> 0.0085082246 | G22: 195.9 | H22: =(G22-G21)/G21 -> 0.0046153846 | I22: 179.9 | J22: =(I22-I21)/I21 -> 0.0078431373 | K22: 179.5 | L22: =(K22-K21)/K21 -> 0.0039149888 | M22: 169.5 | N22: =(M22-M21)/M21 -> 0.0059347181 | O22: 177.8 | P22: =(O22-O21)/O21 -> 0.0056561086 | Q22: 162.3 | R22: =(Q22-Q21)/Q21 -> 0.0024706609 | S22: 167.6 | T22: =(S22-S21)/S21 -> 0.0041941282 | U22: 173.1 | V22: =(U22-U21)/U21 -> 0.0046430644 | W22: 170.9 | X22: =(W22-W21)/W21 -> -0.0017523364 | Y22: 169.7 | Z22: =(Y22-Y21)/Y21 -> 0.0035481963 | AA22: 175.3 | AB22: =(AA22-AA21)/AA21 -> 0.0057372347 | AC22: =VLOOKUP(D22,'crude oil'!A21:E48,4,0) -> 90.71 | AD22: =VLOOKUP(D22,'crude oil'!A21:E48,5,0) -> -0.068685832
A23: Rural+Urban | B23: 2022 | C23: October | D23: 44835 | E23: 179.6 | F23: =(E23-E22)/E22 -> 0.010123735 | G23: 196.3 | H23: =(G23-G22)/G22 -> 0.0020418581 | I23: 181 | J23: =(I23-I22)/I22 -> 0.0061145081 | K23: 180.5 | L23: =(K23-K22)/K22 -> 0.0055710306 | M23: 170.4 | N23: =(M23-M22)/M22 -> 0.0053097345 | O23: 178.7 | P23: =(O23-O22)/O22 -> 0.0050618673 | Q23: 162.9 | R23: =(Q23-Q22)/Q22 -> 0.0036968577 | S23: 168.2 | T23: =(S23-S22)/S22 -> 0.0035799523 | U23: 173.4 | V23: =(U23-U22)/U22 -> 0.0017331023 | W23: 172.1 | X23: =(W23-W22)/W22 -> 0.0070216501 | Y23: 170.5 | Z23: =(Y23-Y22)/Y22 -> 0.0047142015 | AA23: 176.7 | AB23: =(AA23-AA22)/AA22 -> 0.0079863092 | AC23: =VLOOKUP(D23,'crude oil'!A22:E49,4,0) -> 91.7 | AD23: =VLOOKUP(D23,'crude oil'!A22:E49,5,0) -> 0.010913901
A24: Rural+Urban | B24: 2022 | C24: November | D24: 44866 | E24: 178.3 | F24: =(E24-E23)/E23 -> -0.0072383073 | G24: 196.9 | H24: =(G24-G23)/G23 -> 0.0030565461 | I24: 182.1 | J24: =(I24-I23)/I23 -> 0.0060773481 | K24: 181.3 | L24: =(K24-K23)/K23 -> 0.004432133 | M24: 171.4 | N24: =(M24-M23)/M23 -> 0.0058685446 | O24: 179.8 | P24: =(O24-O23)/O23 -> 0.006155568 | Q24: 163 | R24: =(Q24-Q23)/Q23 -> 0.00061387354 | S24: 168.5 | T24: =(S24-S23)/S23 -> 0.001783591 | U24: 173.7 | V24: =(U24-U23)/U23 -> 0.0017301038 | W24: 173.6 | X24: =(W24-W23)/W23 -> 0.0087158629 | Y24: 171.1 | Z24: =(Y24-Y23)/Y23 -> 0.0035190616 | AA24: 176.5 | AB24: =(AA24-AA23)/AA23 -> -0.0011318619 | AC24: =VLOOKUP(D24,'crude oil'!A23:E50,4,0) -> 87.55 | AD24: =VLOOKUP(D24,'crude oil'!A23:E50,5,0) -> -0.04525627
A25: Rural+Urban | B25: 2022 | C25: December | D25: 44896 | E25: 175.9 | F25: =(E25-E24)/E24 -> -0.01346046 | G25: 197.3 | H25: =(G25-G24)/G24 -> 0.0020314881 | I25: 183 | J25: =(I25-I24)/I24 -> 0.0049423394 | K25: 182 | L25: =(K25-K24)/K24 -> 0.0038610039 | M25: 172.1 | N25: =(M25-M24)/M24 -> 0.004084014 | O25: 181.1 | P25: =(O25-O24)/O24 -> 0.0072302558 | Q25: 163.4 | R25: =(Q25-Q24)/Q24 -> 0.0024539877 | S25: 168.9 | T25: =(S25-S24)/S24 -> 0.0023738872 | U25: 174.1 | V25: =(U25-U24)/U24 -> 0.002302821 | W25: 175.8 | X25: =(W25-W24)/W24 -> 0.012672811 | Y25: 172 | Z25: =(Y25-Y24)/Y24 -> 0.0052600818 | AA25: 175.7 | AB25: =(AA25-AA24)/AA24 -> -0.0045325779 | AC25: =VLOOKUP(D25,'crude oil'!A24:E51,4,0) -> 78.1 | AD25: =VLOOKUP(D25,'crude oil'!A24:E51,5,0) -> -0.10793832
A26: Rural+Urban | B26: 2023 | C26: January | D26: 44927 | E26: 176.7 | F26: =(E26-E25)/E25 -> 0.0045480387 | G26: 198.2 | H26: =(G26-G25)/G25 -> 0.0045615813 | I26: 183.8 | J26: =(I26-I25)/I25 -> 0.0043715847 | K26: 182 | L26: =(K26-K25)/K25 -> 0 | M26: 172.9 | N26: =(M26-M25)/M25 -> 0.0046484602 | O26: 182.3 | P26: =(O26-O25)/O25 -> 0.0066261734 | Q26: 163.6 | R26: =(Q26-Q25)/Q25 -> 0.0012239902 | S26: 169.5 | T26: =(S26-S25)/S25 -> 0.0035523979 | U26: 174.3 | V26: =(U26-U25)/U25 -> 0.0011487651 | W26: 178.6 | X26: =(W26-W25)/W25 -> 0.01592719 | Y26: 172.8 | Z26: =(Y26-Y25)/Y25 -> 0.0046511628 | AA26: 176.5 | AB26: =(AA26-AA25)/AA25 -> 0.0045532157 | AC26: =VLOOKUP(D26,'crude oil'!A25:E52,4,0) -> 80.92 | AD26: =VLOOKUP(D26,'crude oil'!A25:E52,5,0) -> 0.036107554
... A28: Rural+Urban | B28: 2023 | C28: March | D28: 44986 | E28: 177 | F28: =(E28-E27)/E27 -> 0 | G28: 199.5 | H28: =(G28-G27)/G27 -> 0 | I28: 185.1 | J28: =(I28-I27)/I27 -> 0 | K28: 181.9 | L28: =(K28-K27)/K27 -> -0.0010982976 | M28: 174.2 | N28: =(M28-M27)/M27 -> 0 | O28: 184.4 | P28: =(O28-O27)/O27 -> 0 | Q28: 164.2 | R28: =(Q28-Q27)/Q27 -> 0 | S28: 170.3 | T28: =(S28-S27)/S27 -> 0 | U28: 175 | V28: =(U28-U27)/U27 -> 0 | W28: 181 | X28: =(W28-W27)/W27 -> 0 | Y28: 174.1 | Z28: =(Y28-Y27)/Y27 -> 0 | AA28: 177.2 | AB28: =(AA28-AA27)/AA27 -> 0 | AC28: =VLOOKUP(D28,'crude oil'!A27:E54,4,0) -> 78.54 | AD28: =VLOOKUP(D28,'crude oil'!A27:E54,5,0) -> -0.045454545

Sheet crude oil
B1: Year | C1: month | D1: price | E1: MOM change
A2: =DATE(B2,MATCH(TRIM(C2),{"January","February","March","April","May","June","July","August","September","October","November","December"},0),1) -> 44197 | B2: 2021 | C2: January | D2: 54.79
A3: =DATE(B3,MATCH(TRIM(C3),{"January","February","March","April","May","June","July","August","September","October","November","December"},0),1) -> 44228 | B3: 2021 | C3: February | D3: 61.22 | E3: =(D3-D2)/D2 -> 0.11735718
A4: =DATE(B4,MATCH(TRIM(C4),{"January","February","March","April","May","June","July","August","September","October","November","December"},0),1) -> 44256 | B4: 2021 | C4: March | D4: 64.73 | E4: =(D4-D3)/D3 -> 0.057334205
A5: =DATE(B5,MATCH(TRIM(C5),{"January","February","March","April","May","June","July","August","September","October","November","December"},0),1) -> 44287 | B5: 2021 | C5: April | D5: 63.4 | E5: =(D5-D4)/D4 -> -0.020546887
A6: =DATE(B6,MATCH(TRIM(C6),{"January","February","March","April","May","June","July","August","September","October","November","December"},0),1) -> 44317 | B6: 2021 | C6: May | D6: 66.95 | E6: =(D6-D5)/D5 -> 0.055993691
A7: =DATE(B7,MATCH(TRIM(C7),{"January","February","March","April","May","June","July","August","September","October","November","December"},0),1) -> 44348 | B7: 2021 | C7: June | D7: 71.98 | E7: =(D7-D6)/D6 -> 0.075130695
A8: =DATE(B8,MATCH(TRIM(C8),{"January","February","March","April","May","June","July","August","September","October","November","December"},0),1) -> 44378 | B8: 2021 | C8: July | D8: 73.54 | E8: =(D8-D7)/D7 -> 0.021672687
A9: =DATE(B9,MATCH(TRIM(C9),{"January","February","March","April","May","June","July","August","September","October","November","December"},0),1) -> 44409 | B9: 2021 | C9: August | D9: 69.8 | E9: =(D9-D8)/D8 -> -0.050856677
A10: =DATE(B10,MATCH(TRIM(C10),{"January","February","March","April","May","June","July","August","September","October","November","December"},0),1) -> 44440 | B10: 2021 | C10: September | D10: 73.13 | E10: =(D10-D9)/D9 -> 0.047707736
A11: =DATE(B11,MATCH(TRIM(C11),{"January","February","March","April","May","June","July","August","September","October","November","December"},0),1) -> 44470 | B11: 2021 | C11: October | D11: 82.11 | E11: =(D11-D10)/D10 -> 0.12279502
A12: =DATE(B12,MATCH(TRIM(C12),{"January","February","March","April","May","June","July","August","September","October","November","December"},0),1) -> 44501 | B12: 2021 | C12: November | D12: 80.64 | E12: =(D12-D11)/D11 -> -0.017902813
A13: =DATE(B13,MATCH(TRIM(C13),{"January","February","March","April","May","June","July","August","September","October","November","December"},0),1) -> 44531 | B13: 2021 | C13: December | D13: 73.3 | E13: =(D13-D12)/D12 -> -0.091021825
A14: =DATE(B14,MATCH(TRIM(C14),{"January","February","March","April","May","June","July","August","September","October","November","December"},0),1) -> 44562 | B14: 2022 | C14: January | D14: 84.67 | E14: =(D14-D13)/D13 -> 0.15511596
... A28: =DATE(B28,MATCH(TRIM(C28),{"January","February","March","April","May","June","July","August","September","October","November","December"},0),1) -> 44986 | B28: 2023 | C28: March | D28: 78.54 | E28: =(D28-D27)/D27 -> -0.045454545

Sheet Data dictnory
A1: Column Name | B1: Column Definition
A2: Sector | B2: Represents the population sector or geographical category for which the CPI data is recorded, such as Rural, Urban, or Rural+Urban.
A3: Year | B3: The calendar year in which the CPI data was recorded.
A4: Month | B4: The month in which the CPI data was recorded.
A5: Cereals and products | B5: CPI index value representing changes in the prices of cereals and cereal-based products.
A6: Meat and fish | B6: CPI index value representing changes in the prices of meat and fish products.
A7: Egg | B7: CPI index value representing changes in the price of eggs.
A8: Milk and products | B8: CPI index value representing changes in the prices of milk and dairy products.
A9: Oils and fats | B9: CPI index value representing changes in the prices of edible oils and fats.
A10: Fruits | B10: CPI index value representing changes in the prices of fruits.
A11: Vegetables | B11: CPI index value representing changes in the prices of vegetables.
A12: Pulses and products | B12: CPI index value representing changes in the prices of pulses and pulse-based products.
... A31: General index | B31: Overall CPI index representing the combined price movement of the entire basket of goods and services.

Sheet Sheet1
A1: Q1 - Which broader category having higher contribution in CPI
M5: All years | AC5: Latest Month may 2023
X11: vs
M25: As we can see Pan,tabacco and intoxicants category having the higher contribution towards CPI 9.36% in yearly pattern and for latest month may 2023 it is 9.39%
A30: Q2 - Which Year having YOY growth more after 2017 also reasons
B34: Years | C34: Y-O-Y Growth | D34: Avg
B35: 2017 | D35: 133.38611
B36: 2018 | C36: =(D36-D35)/D35*100 -> 3.9609321 | D36: 138.66944
B37: 2019 | C37: =(D37-D36)/D36*100 -> 3.935855 | D37: 144.12727
B38: 2020 | C38: =(D38-D37)/D37*100 -> 6.3851394 | D38: 153.33
B39: 2021 | C39: =(D39-D38)/D38*100 -> 5.2740277 | D39: 161.41667
B40: 2022 | C40: =(D40-D39)/D39*100 -> 6.6029943 | D40: 172.075
B41: 2023 | C41: =(D41-D40)/D40*100 -> 3.1953121 | D41: 177.57333
I47: As we can see in year 2022 the yoy growth is 6.60% which is maximum among all other years
L49: possible reasons
L50: 1-Russia–Ukraine War
L51: 2-High Fuel Prices
L52: 3-Global Supply Chain Disruptions
L53: 4-Post-COVID Economic Recovery
A56: Q3
E81: Highest food inflation in month October 2022 and lowest is December 2022 | J81: October | K81: 0.97
J82: December | K82: -1.36
D87: B
G111: Food and beverages have 4.133 of absolute change while spices contribute most absolute change with 30.46
G120: Q4
I149: As per the change % Health and fuel and light is impact most due to covid 19 with 21.86% and 20.14%
A169: Q5
R176: broader categories | S176: correltion
R178: Food and Beverages | S178: =CORREL(Sheet5!F:F,Sheet5!AD:AD) -> 0.10939845
R179: Pan, Tobacco and Intoxicants | S179: =CORREL(Sheet5!H:H,Sheet5!AD:AD) -> 0.13968414
R180: Clothing and Footwear | S180: =CORREL(Sheet5!J:J,Sheet5!AD:AD) -> 0.10496857
R181: Fuel and Light | S181: =CORREL(Sheet5!L:L,Sheet5!AD:AD) -> 0.13261758
R182: Household Goods and Services | S182: =CORREL(Sheet5!N:N,Sheet5!AD:AD) -> -0.004421401
R183: Health | S183: =CORREL(Sheet5!P:P,Sheet5!AD:AD) -> 0.077797237
R184: Transport and Communication | S184: =CORREL(Sheet5!R:R,Sheet5!AD:AD) -> 0.097696081
R185: Recreation and Amusement | S185: =CORREL(Sheet5!T:T,Sheet5!AD:AD) -> 0.12837906
R186: Education | S186: =CORREL(Sheet5!V:V,Sheet5!AD:AD) -> -0.15568221
R187: Personal Care and Effects | S187: =CORREL(Sheet5!X:X,Sheet5!AD:AD) -> -3.7153546e-05
R188: Miscellaneous | S188: =CORREL(Sheet5!Z:Z,Sheet5!AD:AD) -> 0.079750052
R189: General Index | S189: =CORREL(Sheet5!AB:AB,Sheet5!AD:AD) -> 0.13192465
